2019-04-16 14:16:31,268 ERROR: Exception on / [POST] [in c:\users\i355865\onedrive - sap se\xuanyij\projects\playground\venv\lib\site-packages\flask\app.py:1761]
Traceback (most recent call last):
  File "c:\users\i355865\onedrive - sap se\xuanyij\projects\playground\venv\lib\site-packages\redis\connection.py", line 492, in connect
    sock = self._connect()
  File "c:\users\i355865\onedrive - sap se\xuanyij\projects\playground\venv\lib\site-packages\redis\connection.py", line 550, in _connect
    raise err
  File "c:\users\i355865\onedrive - sap se\xuanyij\projects\playground\venv\lib\site-packages\redis\connection.py", line 538, in _connect
    sock.connect(socket_address)
ConnectionRefusedError: [WinError 10061] No connection could be made because the target machine actively refused it

During handling of the above exception, another exception occurred:

Traceback (most recent call last):
  File "c:\users\i355865\onedrive - sap se\xuanyij\projects\playground\venv\lib\site-packages\flask\app.py", line 2292, in wsgi_app
    response = self.full_dispatch_request()
  File "c:\users\i355865\onedrive - sap se\xuanyij\projects\playground\venv\lib\site-packages\flask\app.py", line 1815, in full_dispatch_request
    rv = self.handle_user_exception(e)
  File "c:\users\i355865\onedrive - sap se\xuanyij\projects\playground\venv\lib\site-packages\flask\app.py", line 1718, in handle_user_exception
    reraise(exc_type, exc_value, tb)
  File "c:\users\i355865\onedrive - sap se\xuanyij\projects\playground\venv\lib\site-packages\flask\_compat.py", line 35, in reraise
    raise value
  File "c:\users\i355865\onedrive - sap se\xuanyij\projects\playground\venv\lib\site-packages\flask\app.py", line 1813, in full_dispatch_request
    rv = self.dispatch_request()
  File "c:\users\i355865\onedrive - sap se\xuanyij\projects\playground\venv\lib\site-packages\flask\app.py", line 1799, in dispatch_request
    return self.view_functions[rule.endpoint](**req.view_args)
  File "C:\Users\i355865\OneDrive - SAP SE\xuanyij\projects\sciretrievalsystem\app\webapp\main\routes.py", line 14, in index
    results = query_processor.process(search_terms)
  File "C:\Users\i355865\OneDrive - SAP SE\xuanyij\projects\sciretrievalsystem\app\query_process.py", line 26, in process
    if self.redis_operator.check(stem):
  File "C:\Users\i355865\OneDrive - SAP SE\xuanyij\projects\sciretrievalsystem\app\query_process.py", line 83, in check
    return Redis(connection_pool=self.pool).get(query)
  File "c:\users\i355865\onedrive - sap se\xuanyij\projects\playground\venv\lib\site-packages\redis\client.py", line 1264, in get
    return self.execute_command('GET', name)
  File "c:\users\i355865\onedrive - sap se\xuanyij\projects\playground\venv\lib\site-packages\redis\client.py", line 772, in execute_command
    connection = pool.get_connection(command_name, **options)
  File "c:\users\i355865\onedrive - sap se\xuanyij\projects\playground\venv\lib\site-packages\redis\connection.py", line 994, in get_connection
    connection.connect()
  File "c:\users\i355865\onedrive - sap se\xuanyij\projects\playground\venv\lib\site-packages\redis\connection.py", line 497, in connect
    raise ConnectionError(self._error_message(e))
redis.exceptions.ConnectionError: Error 10061 connecting to localhost:6379. No connection could be made because the target machine actively refused it.
2019-04-16 14:18:48,946 INFO: SCIRetrieve startup [in C:\Users\i355865\OneDrive - SAP SE\xuanyij\projects\sciretrievalsystem\app\webapp\__init__.py:40]
2019-04-16 14:48:56,044 INFO: SCIRetrieve startup [in C:\Users\i355865\OneDrive - SAP SE\xuanyij\projects\sciretrievalsystem\app\webapp\__init__.py:40]
2019-04-16 14:49:03,481 ERROR: Exception on / [POST] [in c:\users\i355865\onedrive - sap se\xuanyij\projects\playground\venv\lib\site-packages\flask\app.py:1761]
Traceback (most recent call last):
  File "c:\users\i355865\onedrive - sap se\xuanyij\projects\playground\venv\lib\site-packages\flask\app.py", line 2292, in wsgi_app
    response = self.full_dispatch_request()
  File "c:\users\i355865\onedrive - sap se\xuanyij\projects\playground\venv\lib\site-packages\flask\app.py", line 1815, in full_dispatch_request
    rv = self.handle_user_exception(e)
  File "c:\users\i355865\onedrive - sap se\xuanyij\projects\playground\venv\lib\site-packages\flask\app.py", line 1718, in handle_user_exception
    reraise(exc_type, exc_value, tb)
  File "c:\users\i355865\onedrive - sap se\xuanyij\projects\playground\venv\lib\site-packages\flask\_compat.py", line 35, in reraise
    raise value
  File "c:\users\i355865\onedrive - sap se\xuanyij\projects\playground\venv\lib\site-packages\flask\app.py", line 1813, in full_dispatch_request
    rv = self.dispatch_request()
  File "c:\users\i355865\onedrive - sap se\xuanyij\projects\playground\venv\lib\site-packages\flask\app.py", line 1799, in dispatch_request
    return self.view_functions[rule.endpoint](**req.view_args)
  File "C:\Users\i355865\OneDrive - SAP SE\xuanyij\projects\sciretrievalsystem\app\webapp\main\routes.py", line 13, in index
    query_processor = QueryProcessor()
  File "C:\Users\i355865\OneDrive - SAP SE\xuanyij\projects\sciretrievalsystem\app\query_process.py", line 21, in __init__
    self.redis_operator = RedisOperator(REDIS_HOST, REDIS_PORT,
NameError: name 'REDIS_HOST' is not defined
2019-04-16 14:49:52,529 INFO: SCIRetrieve startup [in C:\Users\i355865\OneDrive - SAP SE\xuanyij\projects\sciretrievalsystem\app\webapp\__init__.py:40]
2019-04-16 14:49:58,728 ERROR: Exception on / [POST] [in c:\users\i355865\onedrive - sap se\xuanyij\projects\playground\venv\lib\site-packages\flask\app.py:1761]
Traceback (most recent call last):
  File "c:\users\i355865\onedrive - sap se\xuanyij\projects\playground\venv\lib\site-packages\flask\app.py", line 2292, in wsgi_app
    response = self.full_dispatch_request()
  File "c:\users\i355865\onedrive - sap se\xuanyij\projects\playground\venv\lib\site-packages\flask\app.py", line 1815, in full_dispatch_request
    rv = self.handle_user_exception(e)
  File "c:\users\i355865\onedrive - sap se\xuanyij\projects\playground\venv\lib\site-packages\flask\app.py", line 1718, in handle_user_exception
    reraise(exc_type, exc_value, tb)
  File "c:\users\i355865\onedrive - sap se\xuanyij\projects\playground\venv\lib\site-packages\flask\_compat.py", line 35, in reraise
    raise value
  File "c:\users\i355865\onedrive - sap se\xuanyij\projects\playground\venv\lib\site-packages\flask\app.py", line 1813, in full_dispatch_request
    rv = self.dispatch_request()
  File "c:\users\i355865\onedrive - sap se\xuanyij\projects\playground\venv\lib\site-packages\flask\app.py", line 1799, in dispatch_request
    return self.view_functions[rule.endpoint](**req.view_args)
  File "C:\Users\i355865\OneDrive - SAP SE\xuanyij\projects\sciretrievalsystem\app\webapp\main\routes.py", line 13, in index
    query_processor = QueryProcessor()
  File "C:\Users\i355865\OneDrive - SAP SE\xuanyij\projects\sciretrievalsystem\app\query_process.py", line 28, in __init__
    self.es = Elasticsearch("http://" + self.ELASTICSEARCH_HOST + ":" + self.ELASTICSEARCH_PORT)
TypeError: can only concatenate str (not "int") to str
2019-04-16 14:50:31,454 INFO: SCIRetrieve startup [in C:\Users\i355865\OneDrive - SAP SE\xuanyij\projects\sciretrievalsystem\app\webapp\__init__.py:40]
